<?xml version="1.0"?>
<robot name="ArmProject">

  <material name="base_v1_material">
     <color rgba="1.0 1.0 0.5 1"/>
  </material>

  <material name="motor_1_v4_material">
    <color rgba="0.647059 0.647059 0.647059 1"/>
  </material>

  <material name="eslabon_r2_v3_material">
     <color rgba="0.627451 0.627451 0.627451 1"/>
  </material>

  <material name="motor_2_v2_material">
    <color rgba="0.627451 0.627451 0.627451 1"/>
  </material>

  <material name="motor_3_v1_2_material">
    <color rgba="0.627451 0.627451 0.627451 1"/>
  </material>

  <material name="codo_1_modificado_v1_material">
    <color rgba="0.627451 0.627451 0.627451 1"/>
  </material>

  <material name="eslabon_r3_v1_material">
    <color rgba="0.627451 0.627451 0.627451 1"/>
  </material>

  <material name="motor_4_v4_material">
    <color rgba="0.627451 0.627451 0.627451 1"/>
  </material>

  <material name="motor_5_v1_material">
    <color rgba="0.627451 0.627451 0.627451 1"/>
  </material>

  <material name="motor_6_v1_material">
    <color rgba="0.627451 0.627451 0.627451 1"/>
  </material>

  <material name="endEfector_material">
    <color rgba="0.7 0.3 0.7 1"/>
  </material>

  <material name="ventosa_material">
    <color rgba="0.4 0.7 0.9 1"/>
  </material>

  <link name="world"/>

  <!-- base_link -->
  <link name="base_link">
  
    <inertial>
      <origin xyz="0 0 0" rpy="0 0 0"/>
      <mass value="0.250987"/>
      <inertia ixx="0.000229101" ixy="-1.82987e-20" ixz="1.50736e-21" 
               iyy="0.000229101" iyz="-2.57961e-21" izz="0.000443337"/>
    </inertial>
    
    <visual>
      <origin xyz="0 0 0" 
              rpy="-1.06778e-17 8.97091e-18 -1.91402"/>
      <geometry>
        <mesh filename="package://ur5Model/meshes/base_v1.stl" scale="0.001 0.001 0.001"/>
      </geometry>
      <material name="base_v1_material"/>
    </visual>
    
    <collision>
      <origin xyz="0 0 0" rpy="-1.06778e-17 8.97091e-18 -1.91402"/>
      <geometry>
        <mesh filename="package://ur5Model/meshes/base_v1.stl" scale="0.001 0.001 0.001"/>
      </geometry>
    </collision>

  </link>

  <!-- Joint from world to base_link -->
  <joint name="world_to_base" type="fixed">
  
    <parent link="world"/>
    <child link="base_link"/>
    <origin xyz="0 0 0" rpy="0 0 0"/>
    
  </joint>

  <!-- motor_1_v4 -->
  <link name="motor_1_v4">
  
    <inertial>
      <origin xyz="0 0 0" rpy="0 0 0"/>
      <mass value="1.01291"/>
      <inertia ixx="0.00178232" ixy="7.18085e-11" ixz="-1.00158e-10" 
               iyy="0.00159644" iyz="-6.26257e-05" izz="0.00117134"/>
    </inertial>
    
    <visual>
      <origin xyz="0 0 0" rpy="0 0 0"/>
      <geometry>
        <mesh filename="package://ur5Model/meshes/motor_1_v4.stl" scale="0.001 0.001 0.001"/>
      </geometry>
      <material name="motor_1_v4_material"/>
    </visual>
    
    <collision>
      <origin xyz="0 0 0" rpy="0 0 0"/>
      <geometry>
        <mesh filename="package://ur5Model/meshes/motor_1_v4.stl" scale="0.001 0.001 0.001"/>
      </geometry>
    </collision>
    
  </link>

  <!-- Joint from base_link to motor_1_v4 -->
  <joint name="base_link_to_motor_1_v4" type="revolute">
  
    <origin xyz="0 0 0.038" rpy="0 0 0"/>
    <parent link="base_link"/>
    <child link="motor_1_v4"/>
    <axis xyz="0 0 1"/>
    <limit effort="10" velocity="10" 
           lower="-3.141592653589793" upper="3.141592653589793"/>
           
  </joint>

  <!-- motor_2_v2 -->
  <link name="motor_2_v2">
  
    <inertial>
      <origin xyz="0 0 0" rpy="0 0 0"/>
      <mass value="0.816866"/>
      <inertia ixx="0.00110433" ixy="2.92716e-10" ixz="7.05982e-11" 
	       iyy="0.000987213" iyz="2.20299e-05" izz="0.000921334"/>
    </inertial>
    
    <visual>
      <origin xyz="0.1055 0 0" rpy="0 -1.5708 3.1415"/>
      <geometry>
        <mesh filename="package://ur5Model/meshes/motor_2_v2.stl" scale="0.001 0.001 0.001"/>
      </geometry>
	<material name="motor_2_v2_material"/>
    </visual>
    
    <collision>
      <origin xyz="0.1055 0 0" rpy="0 -1.5708 3.1415"/>
      <geometry>
        <mesh filename="package://ur5Model/meshes/motor_2_v2.stl" scale="0.001 0.001 0.001"/>
      </geometry>
    </collision>
    
  </link>

  <!--  Joint from motor_1_v4 to motor_2_v2 -->
  <joint name="motor_1_v4_to_motor_2_v2" type="revolute">
  
    <origin xyz="0 0 0.043" rpy="0 0 0"/>
    <parent link="motor_1_v4"/>
    <child link="motor_2_v2"/>
    <axis xyz="1 0 0"/>
    <limit effort="10" velocity="10" 
	   lower="-0.35" upper="0.35"/>
	   
  </joint>

  <!-- Eslabon_r2_v3 -->
  <link name="eslabon_r2_v3">
  
    <inertial>
      <origin xyz="0 0 0" rpy="0 0 0"/>
      <mass value="0.620599"/>
      <inertia ixx="0.0030008" ixy="3.77221e-18" ixz="-4.6312e-18" 
	       iyy="0.0030008" iyz="-2.72855e-18" izz="0.000298815"/>
    </inertial>
    
    <visual>
      <origin xyz="0.1485 0 0.08" rpy="0 0 0"/>
      <geometry>
        <mesh filename="package://ur5Model/meshes/eslabon_r2_v3.stl" scale="0.001 0.001 0.001"/>
      </geometry>
	<material name="eslabon_r2_v3_material"/>
    </visual>
    
    <collision>
      <origin xyz="0.1485 0 0.08" rpy="0 0 0"/>
      <geometry>
        <mesh filename="package://ur5Model/meshes/eslabon_r2_v3.stl" scale="0.001 0.001 0.001"/>
      </geometry>
    </collision>
    
  </link>

  <!-- Joint from eslabon_r2_v3 to motor_2_v2 -->
  <joint name="motor_2_v2_to_eslabon_r2_v3" type="fixed">
  
    <origin xyz="0 0 0" rpy="0 0 0"/>
    <parent link="motor_2_v2"/>
    <child link="eslabon_r2_v3"/>
    
  </joint>

  <!-- Motor_3_v1_2 -->
  <link name="motor_3_v1_2">
  
    <inertial>
      <origin xyz="0 0 0" rpy="0 0 0"/>
      <mass value="0.816866"/>
      <inertia ixx="0.000987213" ixy="2.92716e-10" ixz="2.20299e-05" 
               iyy="0.00110433" iyz="7.05982e-11" izz="0.000921334"/>
    </inertial>
    
    <visual>
      <origin xyz="0.1055 0 0.36" rpy="0 1.5708 0"/>
      <geometry>
        <mesh filename="package://ur5Model/meshes/motor_3_v1__2.stl" scale="0.001 0.001 0.001"/>
      </geometry>
        <material name="motor_3_v1_2_material"/>
    </visual>
    
    <collision>
      <origin xyz="0.1055 0 0.36" rpy="0 1.5708 0"/>
      <geometry>
        <mesh filename="package://ur5Model/meshes/motor_3_v1__2.stl" scale="0.001 0.001 0.001"/>
      </geometry>
    </collision>
    
  </link>

  <!-- Joint from eslabon_r2_v3 to motor_3_v1_2 -->
  <joint name="eslabon_r2_v3_to_motor_3_v1_2" type="fixed">
  
    <origin xyz="0 0 0" rpy="0 0 0"/>
    <parent link="eslabon_r2_v3"/>
    <child link="motor_3_v1_2"/>
    
  </joint>

  <!-- Codo_1_modificado_v1 -->
  <link name="codo_1_modificado_v1">
  
    <inertial>
      <origin xyz="0 0 0" rpy="0 0 0"/>
      <mass value="1e-09"/>
      <inertia ixx="1e-09" ixy="0" ixz="0" 
	       iyy="1e-09" iyz="0" izz="1e-09"/>
    </inertial>
    
    <visual>
      <origin xyz="0.037 0 0" rpy="0 3.1416 1.5708"/>
      <geometry>
        <mesh filename="package://ur5Model/meshes/codo_1_modificado_v1.stl" scale="0.001 0.001 0.001"/>
      </geometry>
        <material name="codo_1_modificado_v1_material"/>
    </visual>
    
    <collision>
      <origin xyz="0.037 0 0" rpy="0 3.1416 1.5708"/>
      <geometry>
        <mesh filename="package://ur5Model/meshes/codo_1_modificado_v1.stl" scale="0.001 0.001 0.001"/>
      </geometry>
    </collision>
    
  </link>

  <!--  Joint from motor_3_v1_2 to codo_1_modificado_v1 -->
  <joint name="motor_3_v1_2_to_codo_1_modificado_v1" type="revolute">
  
    <origin xyz="0 0 0.36" rpy="0 0 0"/>
    <parent link="motor_3_v1_2"/>
    <child link="codo_1_modificado_v1"/>
    <axis xyz="1 0 0"/>
    <limit effort="10" velocity="10" 
	   lower="-0.35" upper="0.35"/>
	   
  </joint>

  <!-- Link eslabon_r3_v1 -->
  <link name="eslabon_r3_v1">
  
    <inertial>
      <origin xyz="0 0 0" rpy="0 0 0"/>
      <mass value="0.34984"/>
      <inertia ixx="0.0014369" ixy="-1.26022e-17" ixz="6.08888e-18" 
	       iyy="0.0014369" iyz="9.50174e-19" izz="7.54301e-05"/>
    </inertial>
    
    <visual>
      <origin xyz="0.0085 0 0.2425" rpy="0 3.1416 0"/>
      <geometry>
        <mesh filename="package://ur5Model/meshes/eslabon_r3_v1.stl" scale="0.001 0.001 0.001"/>
      </geometry>
        <material name="eslabon_r3_v1_material"/>
    </visual>
    
    <collision>
      <origin xyz="0.0085 0 0.2425" rpy="0 3.1416 0"/>
      <geometry>
        <mesh filename="package://ur5Model/meshes/eslabon_r3_v1.stl" scale="0.001 0.001 0.001"/>
      </geometry>
    </collision>
    
  </link>

  <!-- Joint from codo_1_modificado_v1 to eslabon_r3_v1 -->
  <joint name="codo_1_modificado_v1_to_eslabon_r3_v1 " type="fixed">
  
    <origin xyz="0 0 0" rpy="0 0 0"/>
    <parent link="codo_1_modificado_v1"/>
    <child link="eslabon_r3_v1"/>
    
  </joint>

  <!-- Link motor_4_v4 -->
  <link name="motor_4_v4">
  
    <inertial>
      <origin xyz="0 0 0" rpy="0 0 0"/>
      <mass value="0.283781"/>
      <inertia ixx="0.000261052" ixy="3.32034e-07" ixz="-1.40786e-07" 
               iyy="0.00019133" iyz="2.9564e-05" izz="0.000161552"/>
    </inertial>
    
    <visual>
      <origin xyz="0.0085 -0.014 0.28" rpy="0 0 0"/>
      <geometry>
        <mesh filename="package://ur5Model/meshes/motor_4_v4.stl" scale="0.001 0.001 0.001"/>
      </geometry>
        <material name="motor_4_v4_material"/>
    </visual>
    
    <collision>
      <origin xyz="0.0085 -0.014 0.28" rpy="0 0 0"/>
      <geometry>
        <mesh filename="package://ur5Model/meshes/motor_4_v4.stl" scale="0.001 0.001 0.001"/>
      </geometry>
    </collision>
    
  </link>

  <!-- Joint from eslabon_r3_v1 to motor_4_v4 -->
  <joint name="eslabon_r3_v1_to_motor_4_v4 " type="fixed">
  
    <origin xyz="0 0 0" rpy="0 0 0"/>
    <parent link="eslabon_r3_v1"/>
    <child link="motor_4_v4"/>
    
  </joint>

  <!-- Link motor_5_v1 -->
  <link name="motor_5_v1">
  
    <inertial>
      <origin xyz="0 0 0" rpy="0 0 0"/>
      <mass value="0.283781"/>
      <inertia ixx="0.000248879" ixy="-2.64697e-05" ixz="1.23537e-05" 
               iyy="0.000203503" iyz="2.68595e-05" izz="0.000161552"/>
    </inertial>
    
    <visual>
      <origin xyz="0.108 0.0145 0" rpy="0 -1.5708 3.1416"/>
      <geometry>
        <mesh filename="package://ur5Model/meshes/motor_5_v1.stl" scale="0.001 0.001 0.001"/>
      </geometry>
        <material name="motor_5_v1_material"/>
    </visual>
    
    <collision>
      <origin xyz="0.108 0.0145 0" rpy="0 -1.5708 3.1416"/>
      <geometry>
        <mesh filename="package://ur5Model/meshes/motor_5_v1.stl" scale="0.001 0.001 0.001"/>
      </geometry>
    </collision>
    
  </link>

  <!-- Joint from motor_4_v4 to motor_5_v1  -->
  <joint name="motor_4_v4_to_motor_5_v1" type="revolute">
  
    <origin xyz="0 0.0005 0.2905" rpy="0 0 0"/>
    <parent link="motor_4_v4"/>
    <child link="motor_5_v1"/>
    <axis xyz="1 0 0"/>
    <limit effort="10" velocity="10" lower="-0.35" upper="0.35"/>
    
  </joint>

  <!-- Link motor_6_v1 -->
  <link name="motor_6_v1">
  
    <inertial>
      <origin xyz="0 0 0" rpy="0 0 0"/>
      <mass value="0.283781"/>
      <inertia ixx="0.000224033" ixy="4.01588e-05" ixz="-3.59853e-05" 
	       iyy="0.000183912" iyz="1.30664e-05" izz="0.000205988"/>
    </inertial>
    
    <visual>
      <origin xyz="-0.01 -0.014675 0.12" rpy="0 1.5708 0"/>
      <geometry>
        <mesh filename="package://ur5Model/meshes/motor_6_v1.stl" scale="0.001 0.001 0.001"/>
      </geometry>
        <material name="motor_6_v1_material"/>
    </visual>
    
    <collision>
      <origin xyz="-0.01 -0.014675 0.12" rpy="0 1.5708 0"/>
      <geometry>
        <mesh filename="package://ur5Model/meshes/motor_6_v1.stl" scale="0.001 0.001 0.001"/>
      </geometry>
    </collision>
    
  </link>

  <!-- Joint from motor_5_v1 to motor_6_v1 -->
  <joint name="motor_5_v1_to_motor_6_v1" type="revolute">
  
    <origin xyz="0.118 0 0" rpy="0 0 0"/>
    <parent link="motor_5_v1"/>
    <child link="motor_6_v1"/>
    <axis xyz="0 0 1"/>
    <limit effort="10" velocity="10" lower="-1.57" upper="1.57"/>
    
  </joint>

  <!-- Link endEfector -->
  <link name="endEfector">
  
    <inertial>
      <origin xyz="0 0 0" rpy="0 0 0"/>
      <mass value="0.283781"/>
      <inertia ixx="0.000224033" ixy="4.01588e-05" ixz="-3.59853e-05" 
	       iyy="0.000183912" iyz="1.30664e-05" izz="0.000205988"/>
    </inertial>
    
    <visual>
      <origin xyz="-0.11 -0.0251 0" rpy="0 0 0"/>
      <geometry>
        <mesh filename="package://ur5Model/meshes/endEfector.stl"/>
      </geometry>
        <material name="endEfector_material"/>
    </visual>
    
    <collision>
      <origin xyz="-0.11 -0.0251 0" rpy="0 0 0"/>
      <geometry>
        <mesh filename="package://ur5Model/meshes/endEfector.stl"/>
      </geometry>
    </collision>
    
  </link>

  <!-- Joint from motor_6_v1 to endEfector -->
  <joint name="motor_6_v1_to_endEfector" type="revolute">
  
    <origin xyz="0 0 0.12" rpy="0 0 0"/>
    <parent link="motor_6_v1"/>
    <child link="endEfector"/>
    <axis xyz="1 0 0"/>
    <limit effort="10" velocity="10" lower="-3.141592653589793" upper="3.141592653589793"/>
    
  </joint>

  <!-- ventosa-->
  <link name="ventosa">
  
    <inertial>
      <origin xyz="0 0 0" rpy="0 0 0"/>
      <mass value="0.34984"/>
      <inertia ixx="0.0014369" ixy="-1.26022e-17" ixz="6.08888e-18" 
	       iyy="0.0014369" iyz="9.50174e-19" izz="7.54301e-05"/>
    </inertial>
    
    <visual>
      <origin xyz="0 0 0" rpy="-1.5708 0 0"/>
      <geometry>
        <mesh filename="package://ur5Model/meshes/ventosa.stl" scale="0.0005 0.0005 0.0005"/>
      </geometry>
        <material name="ventosa_material"/>
    </visual>
    
    <collision>
      <origin xyz="0 0 0" rpy="-1.5708 0 0"/>
      <geometry>
        <mesh filename="package://ur5Model/meshes/ventosa.stl" scale="0.0005 0.0005 0.0005"/>
      </geometry>
    </collision>
    
  </link>

  <!-- Joint from endEfector to ventosa -->
  <joint name="endEfector_to_ventosa " type="fixed">
  
    <origin xyz="-0.11 -0.055 0" rpy="0 0 0"/>
    <parent link="endEfector"/>
    <child link="ventosa"/>
    
  </joint>

</robot>
